Workbook

Sheet 01_C_Tactic
A1: 범죄자 원자 Tactic 16개
A2: 범죄자가 달성하려는 범죄 목적을 원자 단위로 정의함. 복합 목적은 08_Tactic조합과 tactic_ids 배열로만 표현
A4: tactic_id | B4: code | C4: 명칭 | D4: 정의 | E4: Technique매핑수
A5: XR-C-TA0001 | B5: criminal_target_discovery | C5: 범죄 대상 탐색 | D5: 잠재적 구매자, 이용자, 피해자 또는 가담 후보의 관심·반응·접촉 가능성을 식별한다. | E5: =COUNTIF('04_C_TA_TE_매핑'!$B$5:$B$500,A5) -> 3
A6: XR-C-TA0002 | B6: deceptive_credibility_manipulation | C6: 범죄 신뢰 조작 | D6: 허위 전문성·성과·후기·정체성을 이용해 불법 제안과 계정의 신뢰성을 조작한다. | E6: =COUNTIF('04_C_TA_TE_매핑'!$B$5:$B$500,A6) -> 8
A7: XR-C-TA0003 | B7: illicit_offer_exposure | C7: 불법 제공물 노출 | D7: 불법 상품·서비스·콘텐츠·정보의 존재와 이용 가능성을 플랫폼 이용자에게 노출한다. | E7: =COUNTIF('04_C_TA_TE_매핑'!$B$5:$B$500,A7) -> 8
A8: XR-C-TA0004 | B8: illicit_demand_acquisition | C8: 불법 수요자 확보 | D8: 불법 상품·서비스·콘텐츠의 구매자, 이용자 또는 의뢰자를 확보한다. | E8: =COUNTIF('04_C_TA_TE_매핑'!$B$5:$B$500,A8) -> 12
A9: XR-C-TA0005 | B9: criminal_collaborator_recruitment | C9: 범죄 가담자 확보 | D9: 공범, 운반책, 계좌·계정 제공자 등 범죄 실행 또는 지원 역할의 참여자를 확보한다. | E9: =COUNTIF('04_C_TA_TE_매핑'!$B$5:$B$500,A9) -> 3
A10: XR-C-TA0006 | B10: offplatform_contact_transition | C10: 외부 접촉 전환 | D10: 공개 플랫폼에서 외부 사이트·메신저·단체방 또는 비공개 접촉 경로로 이동시킨다. | E10: =COUNTIF('04_C_TA_TE_매핑'!$B$5:$B$500,A10) -> 5
A11: XR-C-TA0007 | B11: illicit_value_acquisition | C11: 불법 대가 획득 | D11: 금전, 가상자산, 계정, 정보 또는 기타 경제적 가치의 이전을 유도해 범죄 수익을 확보한다. | E11: =COUNTIF('04_C_TA_TE_매핑'!$B$5:$B$500,A11) -> 5
A12: XR-C-TA0008 | B12: personal_data_credential_acquisition | C12: 개인정보·인증정보 확보 | D12: 개인정보, 인증정보, 계정 접근정보 또는 신원확인 자료를 범죄 목적으로 확보한다. | E12: =COUNTIF('04_C_TA_TE_매핑'!$B$5:$B$500,A12) -> 3
A13: XR-C-TA0009 | B13: illicit_commission_acquisition | C13: 불법 제작 의뢰 확보 | D13: 불법 콘텐츠 또는 범죄 목적 자료의 제작 요청과 요구사항을 확보한다. | E13: =COUNTIF('04_C_TA_TE_매핑'!$B$5:$B$500,A13) -> 3
A14: XR-C-TA0010 | B14: illicit_content_production | C14: 불법 콘텐츠 제작 | D14: 실험 환경에서 범죄 콘텐츠를 대표하는 합성·가상 자산을 생성하거나 구성한다. | E14: =COUNTIF('04_C_TA_TE_매핑'!$B$5:$B$500,A14) -> 1
A15: XR-C-TA0011 | B15: victim_identification | C15: 피해자 특정 | D15: 가상 피해자를 구별할 수 있는 이름·계정·지역·이미지 등 식별 단서를 선택하고 결합한다. | E15: =COUNTIF('04_C_TA_TE_매핑'!$B$5:$B$500,A15) -> 1
A16: XR-C-TA0012 | B16: victim_information_exposure | C16: 피해자 정보 노출 | D16: 가상 피해자의 식별정보를 범죄 콘텐츠 또는 게시 맥락과 결합해 공개한다. | E16: =COUNTIF('04_C_TA_TE_매핑'!$B$5:$B$500,A16) -> 2
... A20: XR-C-TA0016 | B20: enforcement_evasion | C20: 제재 회피 | D20: 삭제·제한·정지 이후 수정 재발행, 대체 계정 또는 공개범위 변경으로 활동 중단을 회피한다. | E20: =COUNTIF('04_C_TA_TE_매핑'!$B$5:$B$500,A20) -> 4

Sheet 02_C_Technique
A1: 범죄자 Technique 37개
A2: 범죄 목적을 달성하기 위한 재사용 가능한 방법. 자체 Procedure와 플랫폼 공통 TTP 의존성을 함께 가짐
A4: technique_id | B4: code | C4: 명칭 | D4: 정의 | E4: 분류 | F4: 주요파라미터 | G4: 플랫폼의존설명 | H4: Tactic매핑수 | I4: 범죄Procedure수 | J4: 플랫폼의존수
A5: XR-C-TE0001 | B5: benign_criminal_content_mixing | C5: 정상·범죄 콘텐츠 혼합 배치 | D5: 7일 실행 큐에 정상 콘텐츠와 범죄 관련 합성 콘텐츠를 설정 비율과 순서로 혼합한다. | E5: 오케스트레이션 | F5: criminal_ratio, sequence_pattern, cycle_days | G5: 각 사건의 실제 발행은 플랫폼 공통 Procedure가 수행 | H5: =COUNTIF('04_C_TA_TE_매핑'!$C$5:$C$500,A5) -> 2 | I5: =COUNTIF('05_C_TE_PR_매핑'!$B$5:$B$500,A5) -> 2 | J5: =COUNTIF('06_플랫폼의존'!$B$5:$B$1000,A5) -> 4
A6: XR-C-TE0002 | B6: expertise_signaling | C6: 전문성 암시 | D6: 가상 전문성·경력·일관된 설명을 이용해 범죄 제안의 신뢰도를 조작한다. | E6: 기망표현 | F6: claim_template_id, strength | G6: 범죄 의미를 구성한 뒤 공통 본문 설정·발행 실행 | H6: =COUNTIF('04_C_TA_TE_매핑'!$C$5:$C$500,A6) -> 1 | I6: =COUNTIF('05_C_TE_PR_매핑'!$B$5:$B$500,A6) -> 1 | J6: =COUNTIF('06_플랫폼의존'!$B$5:$B$1000,A6) -> 5
A7: XR-C-TE0003 | B7: engagement_probe_post | C7: 불법 문의·반응 탐색 게시 | D7: 문의·답글·참여를 유도한 뒤 가상 반응 신호로 관심 대상군을 탐색한다. | E7: 대상탐색 | F7: prompt_template_id, action_type, signal_window | G7: 게시 전 대상 선택과 게시 후 반응 평가를 이산사건으로 연결 | H7: =COUNTIF('04_C_TA_TE_매핑'!$C$5:$C$500,A7) -> 3 | I7: =COUNTIF('05_C_TE_PR_매핑'!$B$5:$B$500,A7) -> 3 | J7: =COUNTIF('06_플랫폼의존'!$B$5:$B$1000,A7) -> 7
A8: XR-C-TE0004 | B8: interest_marker_insertion | C8: 관심 표식 삽입 | D8: 합성 키워드·해시태그·관심 표식을 포함해 특정 집단의 검색·주제 노출 가능성을 높인다. | E8: 노출 | F8: marker_set_id, max_markers | G8: 합성 표식 값을 공통 해시태그 삽입 Procedure에 전달 | H8: =COUNTIF('04_C_TA_TE_매핑'!$C$5:$C$500,A8) -> 3 | I8: =COUNTIF('05_C_TE_PR_매핑'!$B$5:$B$500,A8) -> 1 | J8: =COUNTIF('06_플랫폼의존'!$B$5:$B$1000,A8) -> 4
A9: XR-C-TE0005 | B9: fabricated_outcome_evidence | C9: 허위 성과·증빙 제시 | D9: 가상 성과 주장과 선택적 합성 증빙 자산을 결합해 범죄 제안의 신뢰도를 조작한다. | E9: 기망표현 | F9: outcome_template_id, magnitude_level, evidence_type | G9: 증빙 자산 첨부는 이미지·영상 공통 Procedure 중 하나를 사용 | H9: =COUNTIF('04_C_TA_TE_매핑'!$C$5:$C$500,A9) -> 2 | I9: =COUNTIF('05_C_TE_PR_매핑'!$B$5:$B$500,A9) -> 2 | J9: =COUNTIF('06_플랫폼의존'!$B$5:$B$1000,A9) -> 6
A10: XR-C-TE0006 | B10: fabricated_testimonial | C10: 허위 후기 제시 | D10: 가상 인물의 이용 후기·성공 경험을 합성하여 다수의 신뢰가 존재하는 것처럼 표현한다. | E10: 기망표현 | F10: testimonial_template_id, persona_stub_id | G10: 가상 인물만 사용하고 실제 사용자 후기는 사용하지 않음 | H10: =COUNTIF('04_C_TA_TE_매핑'!$C$5:$C$500,A10) -> 2 | I10: =COUNTIF('05_C_TE_PR_매핑'!$B$5:$B$500,A10) -> 1 | J10: =COUNTIF('06_플랫폼의존'!$B$5:$B$1000,A10) -> 5
A11: XR-C-TE0007 | B11: emotional_narrative_manipulation | C11: 감정적 사연 조작 | D11: 가상 일상·피해·관계 사연을 반복 공유하여 정서적 반응과 금전·행동 유도를 강화한다. | E11: 기망표현 | F11: narrative_template_id, emotion, intensity | G11: 플랫폼 공통 정서 표현 형식 위에 범죄 의도를 추가 | H11: =COUNTIF('04_C_TA_TE_매핑'!$C$5:$C$500,A11) -> 3 | I11: =COUNTIF('05_C_TE_PR_매핑'!$B$5:$B$500,A11) -> 1 | J11: =COUNTIF('06_플랫폼의존'!$B$5:$B$1000,A11) -> 5
A12: XR-C-TE0008 | B12: availability_signaling | C12: 불법 제공물 가용성 제시 | D12: 불법 상품·서비스·콘텐츠가 현재 제공 가능한 것처럼 가상 상태를 표시한다. | E12: 제안표현 | F12: availability_state, quantity_level | G12: 합법 상품 홍보 형식을 상속하되 범죄 의미는 XR-C에 보존 | H12: =COUNTIF('04_C_TA_TE_매핑'!$C$5:$C$500,A12) -> 2 | I12: =COUNTIF('05_C_TE_PR_매핑'!$B$5:$B$500,A12) -> 1 | J12: =COUNTIF('06_플랫폼의존'!$B$5:$B$1000,A12) -> 5
A13: XR-C-TE0009 | B13: illicit_preview_disclosure | C13: 불법 제공물 미리보기 | D13: 합성 범죄자산 일부만 미리보기로 제시해 보유·제공 가능성을 강조한다. | E13: 미디어제안 | F13: synthetic_asset_id, preview_ratio, mask_level | G13: 이미지 또는 영상 첨부 대안 중 자산 유형에 맞는 하나를 선택 | H13: =COUNTIF('04_C_TA_TE_매핑'!$C$5:$C$500,A13) -> 3 | I13: =COUNTIF('05_C_TE_PR_매핑'!$B$5:$B$500,A13) -> 1 | J13: =COUNTIF('06_플랫폼의존'!$B$5:$B$1000,A13) -> 5
A14: XR-C-TE0010 | B14: price_benefit_emphasis | C14: 가격·혜택 강조 | D14: 가상 가격·보상·혜택을 강조해 불법 제공물에 대한 관심과 대가 이전을 유도한다. | E14: 제안표현 | F14: price_band, benefit_template_id | G14: 상품·서비스 홍보 형식과 CTA를 상속 | H14: =COUNTIF('04_C_TA_TE_매핑'!$C$5:$C$500,A14) -> 3 | I14: =COUNTIF('05_C_TE_PR_매핑'!$B$5:$B$500,A14) -> 1 | J14: =COUNTIF('06_플랫폼의존'!$B$5:$B$1000,A14) -> 4
A15: XR-C-TE0011 | B15: scarcity_urgency_signaling | C15: 희소성·긴급성 강조 | D15: 수량·기간·기회가 제한된 것처럼 반복 갱신해 빠른 반응을 유도한다. | E15: 제안표현 | F15: scarcity_type, urgency_level | G15: 반복 갱신 시 플랫폼 상황갱신 Technique과 스케줄 정책 사용 | H15: =COUNTIF('04_C_TA_TE_매핑'!$C$5:$C$500,A15) -> 2 | I15: =COUNTIF('05_C_TE_PR_매핑'!$B$5:$B$500,A15) -> 1 | J15: =COUNTIF('06_플랫폼의존'!$B$5:$B$1000,A15) -> 4
A16: XR-C-TE0012 | B16: legitimate_activity_disguise | C16: 정상 업무·거래 위장 | D16: 범죄 참여·거래 제안을 정상 업무·판매·상담과 유사한 표현 틀로 위장한다. | E16: 위장 | F16: disguise_mode, template_id | G16: 정상 모집·홍보 형식은 플랫폼 공통에서 상속 | H16: =COUNTIF('04_C_TA_TE_매핑'!$C$5:$C$500,A16) -> 3 | I16: =COUNTIF('05_C_TE_PR_매핑'!$B$5:$B$500,A16) -> 1 | J16: =COUNTIF('06_플랫폼의존'!$B$5:$B$1000,A16) -> 5
... A41: XR-C-TE0037 | B41: engagement_signal_scoring | C41: 반응 신호 평가 | D41: 조회·답글·재게시·문의 등 가상 반응을 점수화해 다음 라운드의 대상과 TTP 가중치를 갱신한다. | E41: 대상평가 | F41: signal_window, weights, update_rule | G41: 실행 후 adaptation_history에 점수와 선택 결과를 기록 | H41: =COUNTIF('04_C_TA_TE_매핑'!$C$5:$C$500,A41) -> 2 | I41: =COUNTIF('05_C_TE_PR_매핑'!$B$5:$B$500,A41) -> 1 | J41: =COUNTIF('06_플랫폼의존'!$B$5:$B$1000,A41) -> 3

Sheet 03_C_Procedure
A1: 범죄자 전용 원자 Procedure 41개
A2: 범죄 의미 구성·가상 대상 선택·합성 상태전이·회피·계정 오케스트레이션을 한 번의 함수 호출로 실행한다. 플랫폼 게시 동작은 포함하지 않음
A4: procedure_id | B4: code | C4: 명칭 | D4: 정의 | E4: 실행단계 | F4: executor | G4: parameter_schema | H4: 선행조건 | I4: 실행효과 | J4: 멱등성 | K4: event_type | L4: safety_guard | M4: Technique매핑수
A5: XR-C-PR0001 | B5: select_criminal_intent_template | C5: 범죄 의도 템플릿 선택 | D5: 범죄 분야·행위형·현재 단계에 맞는 합성 콘텐츠 의도 템플릿 하나를 선택한다. | E5: 의도선택 | F5: CriminalContentComposer.select_intent_template | G5: {"profile_id":"string","behavior_pattern_ids":"array<string>","crime_domain_id":"string","phase":"enum","seed":"integer"} | H5: 활성 범죄자 프로필과 합성 콘텐츠 풀이 존재 | I5: draft_plan.content_intent_id 설정 | J5: 동일 seed·입력 멱등 | K5: CRIMINAL_INTENT_SELECTED | L5: synthetic_only | M5: =COUNTIF('05_C_TE_PR_매핑'!$C$5:$C$500,A5) -> 1
A6: XR-C-PR0002 | B6: select_candidate_target_cohort | C6: 후보 대상군 선택 | D6: 가상 사용자 집단에서 설정된 관심·역할 조건을 만족하는 후보 대상군을 선택한다. | E6: 대상선택 | F6: CriminalTargetingExecutor.select_candidate_cohort | G6: {"audience_policy_id":"string","criteria":"object","candidate_limit":"integer","seed":"integer"} | H6: 가상 사용자 집단과 대상 정책 존재 | I6: candidate_target_ids 생성 | J6: 동일 seed·입력 멱등 | K6: TARGET_COHORT_SELECTED | L6: synthetic_users_only | M6: =COUNTIF('05_C_TE_PR_매핑'!$C$5:$C$500,A6) -> 1
A7: XR-C-PR0003 | B7: score_engagement_signals | C7: 반응 신호 점수화 | D7: 후보 대상군의 조회·답글·재게시 등 가상 반응 신호를 점수화한다. | E7: 대상평가 | F7: CriminalTargetingExecutor.score_engagement_signals | G7: {"candidate_target_ids":"array<string>","signal_window":"string","weights":"object"} | H7: 후보 대상군과 시뮬레이션 반응 로그 존재 | I7: target_scores 갱신 | J7: event_id 기준 1회 | K7: ENGAGEMENT_SIGNALS_SCORED | L7: simulation_logs_only | M7: =COUNTIF('05_C_TE_PR_매핑'!$C$5:$C$500,A7) -> 2
A8: XR-C-PR0004 | B8: set_content_mix_plan | C8: 정상·범죄 콘텐츠 혼합 계획 설정 | D8: 7일 실행 큐에서 정상 콘텐츠와 범죄 콘텐츠의 비율·배치 패턴을 설정한다. | E8: 오케스트레이션 | F8: CriminalOrchestrator.set_content_mix_plan | G8: {"cycle_days":"integer","criminal_ratio":"number","sequence_pattern":"enum","seed":"integer"} | H8: 7일 실행 주기와 정상 콘텐츠 풀이 존재 | I8: weekly_event_queue의 콘텐츠 유형 배치 설정 | J8: config_version 기준 멱등 | K8: CONTENT_MIX_PLAN_SET | L8: synthetic_content_only | M8: =COUNTIF('05_C_TE_PR_매핑'!$C$5:$C$500,A8) -> 1
A9: XR-C-PR0005 | B9: insert_illicit_engagement_prompt | C9: 불법 문의·반응 문구 삽입 | D9: 합성 범죄 제안에 대한 문의·답글·참여를 유도하는 템플릿 문구를 초안에 삽입한다. | E9: 콘텐츠편집 | F9: CriminalContentComposer.insert_engagement_prompt | G9: {"draft_id":"string","prompt_template_id":"string","action_type":"enum"} | H9: 초안과 허용된 합성 템플릿 존재 | I9: draft.semantic_blocks에 engagement_prompt 추가 | J9: 동일 템플릿 멱등 | K9: ILLICIT_ENGAGEMENT_PROMPT_INSERTED | L9: template_allowlist_only | M9: =COUNTIF('05_C_TE_PR_매핑'!$C$5:$C$500,A9) -> 1
A10: XR-C-PR0006 | B10: insert_interest_markers | C10: 관심 표식 삽입 | D10: 특정 관심 집단을 나타내는 합성 키워드·해시태그 후보를 초안 메타데이터에 추가한다. | E10: 콘텐츠편집 | F10: CriminalContentComposer.insert_interest_markers | G10: {"draft_id":"string","marker_set_id":"string","max_markers":"integer"} | H10: 초안과 허용 표식 사전 존재 | I10: draft.interest_markers 갱신 | J10: 표식 집합 기준 멱등 | K10: INTEREST_MARKERS_INSERTED | L10: synthetic_vocabulary_only | M10: =COUNTIF('05_C_TE_PR_매핑'!$C$5:$C$500,A10) -> 1
A11: XR-C-PR0007 | B11: insert_expertise_claim | C11: 전문성 주장 삽입 | D11: 가상 전문성·경력·역할을 암시하는 합성 문구를 초안에 추가한다. | E11: 콘텐츠편집 | F11: CriminalContentComposer.insert_expertise_claim | G11: {"draft_id":"string","claim_template_id":"string","strength":"number"} | H11: 초안과 합성 주장 템플릿 존재 | I11: draft.semantic_blocks에 expertise_claim 추가 | J11: 동일 템플릿 멱등 | K11: EXPERTISE_CLAIM_INSERTED | L11: synthetic_claims_only | M11: =COUNTIF('05_C_TE_PR_매핑'!$C$5:$C$500,A11) -> 2
A12: XR-C-PR0008 | B12: insert_fabricated_outcome_claim | C12: 허위 성과 주장 삽입 | D12: 가상 수익·성과·성공 결과를 주장하는 합성 문구를 초안에 추가한다. | E12: 콘텐츠편집 | F12: CriminalContentComposer.insert_fabricated_outcome_claim | G12: {"draft_id":"string","outcome_template_id":"string","magnitude_level":"integer"} | H12: 초안과 합성 성과 템플릿 존재 | I12: draft.semantic_blocks에 fabricated_outcome 추가 | J12: 동일 템플릿 멱등 | K12: FABRICATED_OUTCOME_INSERTED | L12: synthetic_claims_only | M12: =COUNTIF('05_C_TE_PR_매핑'!$C$5:$C$500,A12) -> 1
A13: XR-C-PR0009 | B13: set_fabricated_evidence_asset | C13: 허위 증빙 자산 참조 설정 | D13: 허위 성과 주장을 보강하는 합성 증빙 자산 식별자를 초안에 연결한다. | E13: 콘텐츠편집 | F13: CriminalContentComposer.set_fabricated_evidence_asset | G13: {"draft_id":"string","synthetic_asset_id":"string","evidence_type":"enum"} | H13: 합성 자산 저장소에 자산 존재 | I13: draft.synthetic_evidence_asset_id 설정 | J13: 자산 ID 기준 멱등 | K13: FABRICATED_EVIDENCE_SET | L13: synthetic_assets_only | M13: =COUNTIF('05_C_TE_PR_매핑'!$C$5:$C$500,A13) -> 1
A14: XR-C-PR0010 | B14: insert_fabricated_testimonial | C14: 허위 후기 삽입 | D14: 가상 인물의 성공 경험 또는 이용 후기를 나타내는 합성 텍스트를 초안에 추가한다. | E14: 콘텐츠편집 | F14: CriminalContentComposer.insert_fabricated_testimonial | G14: {"draft_id":"string","testimonial_template_id":"string","persona_stub_id":"string"} | H14: 가상 인물과 합성 후기 템플릿 존재 | I14: draft.semantic_blocks에 fabricated_testimonial 추가 | J14: 동일 템플릿·가상 인물 멱등 | K14: FABRICATED_TESTIMONIAL_INSERTED | L14: synthetic_person_only | M14: =COUNTIF('05_C_TE_PR_매핑'!$C$5:$C$500,A14) -> 1
A15: XR-C-PR0011 | B15: insert_emotional_narrative | C15: 감정적 사연 삽입 | D15: 가상 일상·피해·관계 사연을 이용한 감정 유도 텍스트를 초안에 추가한다. | E15: 콘텐츠편집 | F15: CriminalContentComposer.insert_emotional_narrative | G15: {"draft_id":"string","narrative_template_id":"string","emotion":"enum","intensity":"number"} | H15: 합성 사연 템플릿 존재 | I15: draft.semantic_blocks에 emotional_narrative 추가 | J15: 동일 템플릿 멱등 | K15: EMOTIONAL_NARRATIVE_INSERTED | L15: synthetic_story_only | M15: =COUNTIF('05_C_TE_PR_매핑'!$C$5:$C$500,A15) -> 1
A16: XR-C-PR0012 | B16: insert_availability_claim | C16: 가용 상태 주장 삽입 | D16: 불법 제공물이 현재 이용 가능한 것처럼 표현하는 합성 상태 문구를 추가한다. | E16: 콘텐츠편집 | F16: CriminalContentComposer.insert_availability_claim | G16: {"draft_id":"string","availability_state":"enum","quantity_level":"integer"} | H16: 초안과 분야 변수 존재 | I16: draft.offer.availability 갱신 | J16: 동일 상태 멱등 | K16: AVAILABILITY_CLAIM_INSERTED | L16: simulation_offer_only | M16: =COUNTIF('05_C_TE_PR_매핑'!$C$5:$C$500,A16) -> 1
... A45: XR-C-PR0041 | B45: enqueue_cross_account_actions | C45: 교차계정 확산행위 예약 | D45: 선택된 가상 계정별 재게시·인용·신규 게시 사건을 이산사건 큐에 추가한다. | E45: 확산예약 | F45: CriminalAmplificationExecutor.enqueue_actions | G45: {"source_post_id":"string","account_ids":"array<string>","action_mix":"object","delay_distribution":"object"} | H45: 확산 원본과 계정 집합 선택 완료 | I45: future_event_queue에 계정별 실행 사건 추가 | J45: event_key 기준 멱등 | K45: CROSS_ACCOUNT_ACTIONS_ENQUEUED | L45: synthetic_accounts_only | M45: =COUNTIF('05_C_TE_PR_매핑'!$C$5:$C$500,A45) -> 2

Sheet 04_C_TA_TE_매핑
A1: 범죄자 Tactic–Technique 매핑
A2: Technique이 지원하는 원자 Tactic을 다대다 관계로 저장함. 하나의 Technique이 여러 목적에 기여할 수 있음
A4: mapping_id | B4: tactic_id | C4: technique_id | D4: relation_type | E4: 매핑근거 | F4: mapping_key
A5: XR-C-MT0001 | B5: XR-C-TA0014 | C5: XR-C-TE0001 | D5: supports | E5: 정상·범죄 콘텐츠 혼합 배치이 범죄 활동 지속 달성에 사용됨 | F5: =B5&"|"&C5 -> XR-C-TA0014|XR-C-TE0001
A6: XR-C-MT0002 | B6: XR-C-TA0015 | C6: XR-C-TE0001 | D6: supports | E6: 정상·범죄 콘텐츠 혼합 배치이 탐지 회피 달성에 사용됨 | F6: =B6&"|"&C6 -> XR-C-TA0015|XR-C-TE0001
A7: XR-C-MT0003 | B7: XR-C-TA0002 | C7: XR-C-TE0002 | D7: supports | E7: 전문성 암시이 범죄 신뢰 조작 달성에 사용됨 | F7: =B7&"|"&C7 -> XR-C-TA0002|XR-C-TE0002
A8: XR-C-MT0004 | B8: XR-C-TA0001 | C8: XR-C-TE0003 | D8: supports | E8: 불법 문의·반응 탐색 게시이 범죄 대상 탐색 달성에 사용됨 | F8: =B8&"|"&C8 -> XR-C-TA0001|XR-C-TE0003
A9: XR-C-MT0005 | B9: XR-C-TA0004 | C9: XR-C-TE0003 | D9: supports | E9: 불법 문의·반응 탐색 게시이 불법 수요자 확보 달성에 사용됨 | F9: =B9&"|"&C9 -> XR-C-TA0004|XR-C-TE0003
A10: XR-C-MT0006 | B10: XR-C-TA0005 | C10: XR-C-TE0003 | D10: supports | E10: 불법 문의·반응 탐색 게시이 범죄 가담자 확보 달성에 사용됨 | F10: =B10&"|"&C10 -> XR-C-TA0005|XR-C-TE0003
A11: XR-C-MT0007 | B11: XR-C-TA0001 | C11: XR-C-TE0004 | D11: supports | E11: 관심 표식 삽입이 범죄 대상 탐색 달성에 사용됨 | F11: =B11&"|"&C11 -> XR-C-TA0001|XR-C-TE0004
A12: XR-C-MT0008 | B12: XR-C-TA0003 | C12: XR-C-TE0004 | D12: supports | E12: 관심 표식 삽입이 불법 제공물 노출 달성에 사용됨 | F12: =B12&"|"&C12 -> XR-C-TA0003|XR-C-TE0004
A13: XR-C-MT0009 | B13: XR-C-TA0004 | C13: XR-C-TE0004 | D13: supports | E13: 관심 표식 삽입이 불법 수요자 확보 달성에 사용됨 | F13: =B13&"|"&C13 -> XR-C-TA0004|XR-C-TE0004
A14: XR-C-MT0010 | B14: XR-C-TA0002 | C14: XR-C-TE0005 | D14: supports | E14: 허위 성과·증빙 제시이 범죄 신뢰 조작 달성에 사용됨 | F14: =B14&"|"&C14 -> XR-C-TA0002|XR-C-TE0005
A15: XR-C-MT0011 | B15: XR-C-TA0004 | C15: XR-C-TE0005 | D15: supports | E15: 허위 성과·증빙 제시이 불법 수요자 확보 달성에 사용됨 | F15: =B15&"|"&C15 -> XR-C-TA0004|XR-C-TE0005
A16: XR-C-MT0012 | B16: XR-C-TA0002 | C16: XR-C-TE0006 | D16: supports | E16: 허위 후기 제시이 범죄 신뢰 조작 달성에 사용됨 | F16: =B16&"|"&C16 -> XR-C-TA0002|XR-C-TE0006
... A77: XR-C-MT0073 | B77: XR-C-TA0014 | C77: XR-C-TE0037 | D77: supports | E77: 반응 신호 평가이 범죄 활동 지속 달성에 사용됨 | F77: =B77&"|"&C77 -> XR-C-TA0014|XR-C-TE0037

Sheet 05_C_TE_PR_매핑
A1: 범죄자 Technique–Procedure 매핑
A2: core는 필수 원자 실행, optional은 프로필·확률에 따른 추가 실행. 순서 힌트는 Technique 내부 실행 순서를 나타냄
A4: mapping_id | B4: technique_id | C4: procedure_id | D4: relation_type | E4: order_hint | F4: 실행역할 | G4: mapping_key
A5: XR-C-MP0001 | B5: XR-C-TE0001 | C5: XR-C-PR0001 | D5: core | E5: 1 | F5: 범죄 분야·행위형에 맞는 합성 콘텐츠 의도 템플릿 선택 | G5: =B5&"|"&C5&"|"&D5 -> XR-C-TE0001|XR-C-PR0001|core
A6: XR-C-MP0002 | B6: XR-C-TE0001 | C6: XR-C-PR0004 | D6: core | E6: 2 | F6: 7일 콘텐츠 혼합 계획 설정 | G6: =B6&"|"&C6&"|"&D6 -> XR-C-TE0001|XR-C-PR0004|core
A7: XR-C-MP0003 | B7: XR-C-TE0002 | C7: XR-C-PR0007 | D7: core | E7: 1 | F7: 합성 전문성 주장 삽입 | G7: =B7&"|"&C7&"|"&D7 -> XR-C-TE0002|XR-C-PR0007|core
A8: XR-C-MP0004 | B8: XR-C-TE0003 | C8: XR-C-PR0002 | D8: core | E8: 1 | F8: 후보 대상군 선택 | G8: =B8&"|"&C8&"|"&D8 -> XR-C-TE0003|XR-C-PR0002|core
A9: XR-C-MP0005 | B9: XR-C-TE0003 | C9: XR-C-PR0005 | D9: core | E9: 2 | F9: 범죄 문의·반응 문구 삽입 | G9: =B9&"|"&C9&"|"&D9 -> XR-C-TE0003|XR-C-PR0005|core
A10: XR-C-MP0006 | B10: XR-C-TE0003 | C10: XR-C-PR0003 | D10: optional | E10: 3 | F10: 발행 후 반응 신호 점수화 | G10: =B10&"|"&C10&"|"&D10 -> XR-C-TE0003|XR-C-PR0003|optional
A11: XR-C-MP0007 | B11: XR-C-TE0004 | C11: XR-C-PR0006 | D11: core | E11: 1 | F11: 관심 표식 후보 삽입 | G11: =B11&"|"&C11&"|"&D11 -> XR-C-TE0004|XR-C-PR0006|core
A12: XR-C-MP0008 | B12: XR-C-TE0005 | C12: XR-C-PR0008 | D12: core | E12: 1 | F12: 허위 성과 주장 삽입 | G12: =B12&"|"&C12&"|"&D12 -> XR-C-TE0005|XR-C-PR0008|core
A13: XR-C-MP0009 | B13: XR-C-TE0005 | C13: XR-C-PR0009 | D13: optional | E13: 2 | F13: 합성 증빙 자산 참조 설정 | G13: =B13&"|"&C13&"|"&D13 -> XR-C-TE0005|XR-C-PR0009|optional
A14: XR-C-MP0010 | B14: XR-C-TE0006 | C14: XR-C-PR0010 | D14: core | E14: 1 | F14: 가상 인물 후기 삽입 | G14: =B14&"|"&C14&"|"&D14 -> XR-C-TE0006|XR-C-PR0010|core
A15: XR-C-MP0011 | B15: XR-C-TE0007 | C15: XR-C-PR0011 | D15: core | E15: 1 | F15: 감정적 합성 사연 삽입 | G15: =B15&"|"&C15&"|"&D15 -> XR-C-TE0007|XR-C-PR0011|core
A16: XR-C-MP0012 | B16: XR-C-TE0008 | C16: XR-C-PR0012 | D16: core | E16: 1 | F16: 가상 가용 상태 주장 삽입 | G16: =B16&"|"&C16&"|"&D16 -> XR-C-TE0008|XR-C-PR0012|core
... A57: XR-C-MP0053 | B57: XR-C-TE0037 | C57: XR-C-PR0003 | D57: core | E57: 1 | F57: 가상 반응 신호 점수화 | G57: =B57&"|"&C57&"|"&D57 -> XR-C-TE0037|XR-C-PR0003|core

Sheet 06_플랫폼의존
A1: 범죄자 Technique의 플랫폼 공통 TTP 의존 관계
A2: 범죄자 확장은 XR-P/XR-U 요소를 복제하지 않고 ID로 참조함. alternative_group이 같은 행은 실행 형식에 맞는 대안 묶음
A4: dependency_id | B4: criminal_technique_id | C4: dependency_type | D4: alternative_group | E4: platform_id | F4: platform_type | G4: 선택규칙 | H4: 의존설명 | I4: dependency_key
A5: XR-C-DP0001 | B5: XR-C-TE0001 | C5: required | E5: XR-P-PR0014 | F5: PlatformProcedure | G5: Technique 실행에 필수 | H5: 각 사건의 실제 발행은 플랫폼 공통 Procedure가 수행 | I5: =B5&"|"&C5&"|"&E5 -> XR-C-TE0001|required|XR-P-PR0014
A6: XR-C-DP0002 | B6: XR-C-TE0001 | C6: optional | E6: XR-P-CI0001 | F6: PlatformContentIntent | G6: 프로필·확률·콘텐츠 형식에 따라 추가 | H6: 각 사건의 실제 발행은 플랫폼 공통 Procedure가 수행 | I6: =B6&"|"&C6&"|"&E6 -> XR-C-TE0001|optional|XR-P-CI0001
A7: XR-C-DP0003 | B7: XR-C-TE0001 | C7: optional | E7: XR-P-CI0002 | F7: PlatformContentIntent | G7: 프로필·확률·콘텐츠 형식에 따라 추가 | H7: 각 사건의 실제 발행은 플랫폼 공통 Procedure가 수행 | I7: =B7&"|"&C7&"|"&E7 -> XR-C-TE0001|optional|XR-P-CI0002
A8: XR-C-DP0004 | B8: XR-C-TE0001 | C8: optional | E8: XR-P-SP0003 | F8: PlatformSchedulePolicy | G8: 프로필·확률·콘텐츠 형식에 따라 추가 | H8: 각 사건의 실제 발행은 플랫폼 공통 Procedure가 수행 | I8: =B8&"|"&C8&"|"&E8 -> XR-C-TE0001|optional|XR-P-SP0003
A9: XR-C-DP0005 | B9: XR-C-TE0002 | C9: required | E9: XR-P-TE0001 | F9: PlatformTechnique | G9: Technique 실행에 필수 | H9: 범죄 의미를 구성한 뒤 공통 본문 설정·발행 실행 | I9: =B9&"|"&C9&"|"&E9 -> XR-C-TE0002|required|XR-P-TE0001
A10: XR-C-DP0006 | B10: XR-C-TE0002 | C10: required | E10: XR-P-PR0006 | F10: PlatformProcedure | G10: Technique 실행에 필수 | H10: 범죄 의미를 구성한 뒤 공통 본문 설정·발행 실행 | I10: =B10&"|"&C10&"|"&E10 -> XR-C-TE0002|required|XR-P-PR0006
A11: XR-C-DP0007 | B11: XR-C-TE0002 | C11: required | E11: XR-P-PR0014 | F11: PlatformProcedure | G11: Technique 실행에 필수 | H11: 범죄 의미를 구성한 뒤 공통 본문 설정·발행 실행 | I11: =B11&"|"&C11&"|"&E11 -> XR-C-TE0002|required|XR-P-PR0014
A12: XR-C-DP0008 | B12: XR-C-TE0002 | C12: optional | E12: XR-P-TE0002 | F12: PlatformTechnique | G12: 프로필·확률·콘텐츠 형식에 따라 추가 | H12: 범죄 의미를 구성한 뒤 공통 본문 설정·발행 실행 | I12: =B12&"|"&C12&"|"&E12 -> XR-C-TE0002|optional|XR-P-TE0002
A13: XR-C-DP0009 | B13: XR-C-TE0002 | C13: optional | E13: XR-P-PR0007 | F13: PlatformProcedure | G13: 프로필·확률·콘텐츠 형식에 따라 추가 | H13: 범죄 의미를 구성한 뒤 공통 본문 설정·발행 실행 | I13: =B13&"|"&C13&"|"&E13 -> XR-C-TE0002|optional|XR-P-PR0007
A14: XR-C-DP0010 | B14: XR-C-TE0003 | C14: required | E14: XR-P-TE0013 | F14: PlatformTechnique | G14: Technique 실행에 필수 | H14: 게시 전 대상 선택과 게시 후 반응 평가를 이산사건으로 연결 | I14: =B14&"|"&C14&"|"&E14 -> XR-C-TE0003|required|XR-P-TE0013
A15: XR-C-DP0011 | B15: XR-C-TE0003 | C15: required | E15: XR-P-PR0006 | F15: PlatformProcedure | G15: Technique 실행에 필수 | H15: 게시 전 대상 선택과 게시 후 반응 평가를 이산사건으로 연결 | I15: =B15&"|"&C15&"|"&E15 -> XR-C-TE0003|required|XR-P-PR0006
A16: XR-C-DP0012 | B16: XR-C-TE0003 | C16: required | E16: XR-P-PR0018 | F16: PlatformProcedure | G16: Technique 실행에 필수 | H16: 게시 전 대상 선택과 게시 후 반응 평가를 이산사건으로 연결 | I16: =B16&"|"&C16&"|"&E16 -> XR-C-TE0003|required|XR-P-PR0018
... A46: XR-C-DP0042 | B46: XR-C-TE0009 | C46: required | E46: XR-P-PR0014 | F46: PlatformProcedure | G46: Technique 실행에 필수 | H46: 이미지 또는 영상 첨부 대안 중 자산 유형에 맞는 하나를 선택 | I46: =B46&"|"&C46&"|"&E46 -> XR-C-TE0009|required|XR-P-PR0014
A47: XR-C-DP0043 | B47: XR-C-TE0009 | C47: alternative | D47: 1 | E47: XR-P-TE0002 | F47: PlatformTechnique | G47: 동일 그룹에서 실행 경로에 맞는 한 개 이상 선택 | H47: 이미지 또는 영상 첨부 대안 중 자산 유형에 맞는 하나를 선택 | I47: =B47&"|"&C47&"|"&E47 -> XR-C-TE0009|alternative|XR-P-TE0002
A48: XR-C-DP0044 | B48: XR-C-TE0009 | C48: alternative | D48: 1 | E48: XR-P-TE0003 | F48: PlatformTechnique | G48: 동일 그룹에서 실행 경로에 맞는 한 개 이상 선택 | H48: 이미지 또는 영상 첨부 대안 중 자산 유형에 맞는 하나를 선택 | I48: =B48&"|"&C48&"|"&E48 -> XR-C-TE0009|alternative|XR-P-TE0003
A49: XR-C-DP0045 | B49: XR-C-TE0009 | C49: alternative | D49: 1 | E49: XR-P-PR0007 | F49: PlatformProcedure | G49: 동일 그룹에서 실행 경로에 맞는 한 개 이상 선택 | H49: 이미지 또는 영상 첨부 대안 중 자산 유형에 맞는 하나를 선택 | I49: =B49&"|"&C49&"|"&E49 -> XR-C-TE0009|alternative|XR-P-PR0007
A50: XR-C-DP0046 | B50: XR-C-TE0009 | C50: alternative | D50: 1 | E50: XR-P-PR0008 | F50: PlatformProcedure | G50: 동일 그룹에서 실행 경로에 맞는 한 개 이상 선택 | H50: 이미지 또는 영상 첨부 대안 중 자산 유형에 맞는 하나를 선택 | I50: =B50&"|"&C50&"|"&E50 -> XR-C-TE0009|alternative|XR-P-PR0008
A51: XR-C-DP0047 | B51: XR-C-TE0010 | C51: required | E51: XR-P-TE0028 | F51: PlatformTechnique | G51: Technique 실행에 필수 | H51: 상품·서비스 홍보 형식과 CTA를 상속 | I51: =B51&"|"&C51&"|"&E51 -> XR-C-TE0010|required|XR-P-TE0028
A52: XR-C-DP0048 | B52: XR-C-TE0010 | C52: required | E52: XR-P-PR0006 | F52: PlatformProcedure | G52: Technique 실행에 필수 | H52: 상품·서비스 홍보 형식과 CTA를 상속 | I52: =B52&"|"&C52&"|"&E52 -> XR-C-TE0010|required|XR-P-PR0006
A53: XR-C-DP0049 | B53: XR-C-TE0010 | C53: required | E53: XR-P-PR0018 | F53: PlatformProcedure | G53: Technique 실행에 필수 | H53: 상품·서비스 홍보 형식과 CTA를 상속 | I53: =B53&"|"&C53&"|"&E53 -> XR-C-TE0010|required|XR-P-PR0018
A54: XR-C-DP0050 | B54: XR-C-TE0010 | C54: required | E54: XR-P-PR0014 | F54: PlatformProcedure | G54: Technique 실행에 필수 | H54: 상품·서비스 홍보 형식과 CTA를 상속 | I54: =B54&"|"&C54&"|"&E54 -> XR-C-TE0010|required|XR-P-PR0014
A55: XR-C-DP0051 | B55: XR-C-TE0011 | C55: required | E55: XR-P-PR0006 | F55: PlatformProcedure | G55: Technique 실행에 필수 | H55: 반복 갱신 시 플랫폼 상황갱신 Technique과 스케줄 정책 사용 | I55: =B55&"|"&C55&"|"&E55 -> XR-C-TE0011|required|XR-P-PR0006
A56: XR-C-DP0052 | B56: XR-C-TE0011 | C56: required | E56: XR-P-PR0014 | F56: PlatformProcedure | G56: Technique 실행에 필수 | H56: 반복 갱신 시 플랫폼 상황갱신 Technique과 스케줄 정책 사용 | I56: =B56&"|"&C56&"|"&E56 -> XR-C-TE0011|required|XR-P-PR0014
A57: XR-C-DP0053 | B57: XR-C-TE0011 | C57: optional | E57: XR-P-TE0024 | F57: PlatformTechnique | G57: 프로필·확률·콘텐츠 형식에 따라 추가 | H57: 반복 갱신 시 플랫폼 상황갱신 Technique과 스케줄 정책 사용 | I57: =B57&"|"&C57&"|"&E57 -> XR-C-TE0011|optional|XR-P-TE0024
A58: XR-C-DP0054 | B58: XR-C-TE0011 | C58: optional | E58: XR-P-SP0003 | F58: PlatformSchedulePolicy | G58: 프로필·확률·콘텐츠 형식에 따라 추가 | H58: 반복 갱신 시 플랫폼 상황갱신 Technique과 스케줄 정책 사용 | I58: =B58&"|"&C58&"|"&E58 -> XR-C-TE0011|optional|XR-P-SP0003
A59: XR-C-DP0055 | B59: XR-C-TE0012 | C59: required | E59: XR-P-TE0001 | F59: PlatformTechnique | G59: Technique 실행에 필수 | H59: 정상 모집·홍보 형식은 플랫폼 공통에서 상속 | I59: =B59&"|"&C59&"|"&E59 -> XR-C-TE0012|required|XR-P-TE0001
A60: XR-C-DP0056 | B60: XR-C-TE0012 | C60: required | E60: XR-P-PR0006 | F60: PlatformProcedure | G60: Technique 실행에 필수 | H60: 정상 모집·홍보 형식은 플랫폼 공통에서 상속 | I60: =B60&"|"&C60&"|"&E60 -> XR-C-TE0012|required|XR-P-PR0006
A61: XR-C-DP0057 | B61: XR-C-TE0012 | C61: required | E61: XR-P-PR0014 | F61: PlatformProcedure | G61: Technique 실행에 필수 | H61: 정상 모집·홍보 형식은 플랫폼 공통에서 상속 | I61: =B61&"|"&C61&"|"&E61 -> XR-C-TE0012|required|XR-P-PR0014
A62: XR-C-DP0058 | B62: XR-C-TE0012 | C62: optional | E62: XR-P-TE0026 | F62: PlatformTechnique | G62: 프로필·확률·콘텐츠 형식에 따라 추가 | H62: 정상 모집·홍보 형식은 플랫폼 공통에서 상속 | I62: =B62&"|"&C62&"|"&E62 -> XR-C-TE0012|optional|XR-P-TE0026
... A81: XR-C-DP0077 | B81: XR-C-TE0016 | C81: required | E81: XR-P-PR0014 | F81: PlatformProcedure | G81: Technique 실행에 필수 | H81: 미디어 형식은 자산 유형에 따라 대안 선택 | I81: =B81&"|"&C81&"|"&E81 -> XR-C-TE0016|required|XR-P-PR0014
A82: XR-C-DP0078 | B82: XR-C-TE0016 | C82: alternative | D82: 1 | E82: XR-P-TE0002 | F82: PlatformTechnique | G82: 동일 그룹에서 실행 경로에 맞는 한 개 이상 선택 | H82: 미디어 형식은 자산 유형에 따라 대안 선택 | I82: =B82&"|"&C82&"|"&E82 -> XR-C-TE0016|alternative|XR-P-TE0002
A83: XR-C-DP0079 | B83: XR-C-TE0016 | C83: alternative | D83: 1 | E83: XR-P-TE0003 | F83: PlatformTechnique | G83: 동일 그룹에서 실행 경로에 맞는 한 개 이상 선택 | H83: 미디어 형식은 자산 유형에 따라 대안 선택 | I83: =B83&"|"&C83&"|"&E83 -> XR-C-TE0016|alternative|XR-P-TE0003
A84: XR-C-DP0080 | B84: XR-C-TE0016 | C84: alternative | D84: 1 | E84: XR-P-PR0007 | F84: PlatformProcedure | G84: 동일 그룹에서 실행 경로에 맞는 한 개 이상 선택 | H84: 미디어 형식은 자산 유형에 따라 대안 선택 | I84: =B84&"|"&C84&"|"&E84 -> XR-C-TE0016|alternative|XR-P-PR0007
A85: XR-C-DP0081 | B85: XR-C-TE0016 | C85: alternative | D85: 1 | E85: XR-P-PR0008 | F85: PlatformProcedure | G85: 동일 그룹에서 실행 경로에 맞는 한 개 이상 선택 | H85: 미디어 형식은 자산 유형에 따라 대안 선택 | I85: =B85&"|"&C85&"|"&E85 -> XR-C-TE0016|alternative|XR-P-PR0008
A86: XR-C-DP0082 | B86: XR-C-TE0017 | C86: required | E86: XR-P-TE0001 | F86: PlatformTechnique | G86: Technique 실행에 필수 | H86: 실제 외부 계정이 아닌 합성 식별자만 사용 | I86: =B86&"|"&C86&"|"&E86 -> XR-C-TE0017|required|XR-P-TE0001
A87: XR-C-DP0083 | B87: XR-C-TE0017 | C87: required | E87: XR-P-PR0006 | F87: PlatformProcedure | G87: Technique 실행에 필수 | H87: 실제 외부 계정이 아닌 합성 식별자만 사용 | I87: =B87&"|"&C87&"|"&E87 -> XR-C-TE0017|required|XR-P-PR0006
A88: XR-C-DP0084 | B88: XR-C-TE0017 | C88: required | E88: XR-P-PR0014 | F88: PlatformProcedure | G88: Technique 실행에 필수 | H88: 실제 외부 계정이 아닌 합성 식별자만 사용 | I88: =B88&"|"&C88&"|"&E88 -> XR-C-TE0017|required|XR-P-PR0014
...

Sheet 07_행위형프리셋
A1: 9개 공통 행위형별 범죄자 TTP 프리셋
A2: 41개 범죄자 유형은 주·보조 행위형과 범죄 분야를 결합한다. 이 표는 초기 Tactic·Technique 후보 집합이며 실제 선택은 가중치와 라운드 상태로 결정
A4: behavior_pattern_id | B4: code | C4: 명칭 | D4: 정의 | E4: 권장tactic_ids | F4: 권장criminal_technique_ids | G4: 주요환경설정키 | H4: 분야확장규칙
A5: XR-C-BP0001 | B5: SALE | C5: 판매·거래형 | D5: 불법 제공물의 가용성·가격·접촉경로를 제시하여 수요와 대가 이전을 유도 | E5: XR-C-TA0003; XR-C-TA0004; XR-C-TA0006; XR-C-TA0007; XR-C-TA0014; XR-C-TA0015 | F5: XR-C-TE0008; XR-C-TE0009; XR-C-TE0010; XR-C-TE0011; XR-C-TE0015; XR-C-TE0017; XR-C-TE0018; XR-C-TE0020; XR-C-TE0028; XR-C-TE0030 | G5: criminal_ratio, price_band, offplatform_probability, evasion_strength | H5: 판매 분야에 따라 offer_type·price_band·route_type을 특화
A6: XR-C-BP0002 | B6: DISTRIBUTE | C6: 유포·재유포형 | D6: 동일하거나 변형된 범죄 관련 합성 콘텐츠를 반복 유통·증폭 | E6: XR-C-TA0003; XR-C-TA0013; XR-C-TA0014; XR-C-TA0015; XR-C-TA0016 | F6: XR-C-TE0029; XR-C-TE0030; XR-C-TE0031; XR-C-TE0032; XR-C-TE0034 | G6: action_mix, account_limit, mutation_strength, repost_interval | H6: 콘텐츠 분야가 바뀌어도 확산·회피 패턴은 재사용
A7: XR-C-BP0003 | B7: RECRUIT | C7: 모집형 | D7: 수요자 또는 범죄 가담자의 역할·조건·보상을 제시하고 접촉을 확보 | E7: XR-C-TA0004; XR-C-TA0005; XR-C-TA0006; XR-C-TA0014; XR-C-TA0015 | F7: XR-C-TE0003; XR-C-TE0012; XR-C-TE0014; XR-C-TE0015; XR-C-TE0017; XR-C-TE0018; XR-C-TE0028; XR-C-TE0030 | G7: role_type, eligibility, reward_band, signal_threshold | H7: 수요자 모집과 공범 모집은 Tactic ID로 구분
A8: XR-C-BP0004 | B8: BROKER | C8: 중개·알선형 | D8: 판매자·구매자·의뢰자·제작자를 연결하는 역할을 제시하고 외부 접촉과 대가 이전을 연결 | E8: XR-C-TA0002; XR-C-TA0004; XR-C-TA0006; XR-C-TA0007; XR-C-TA0014 | F8: XR-C-TE0013; XR-C-TE0015; XR-C-TE0017; XR-C-TE0018; XR-C-TE0020; XR-C-TE0028; XR-C-TE0030 | G8: intermediary_role, route_type, pretext_type, update_interval | H8: 분야 특화 변수로 중개 대상과 역할만 변경
A9: XR-C-BP0005 | B9: DECEIVE | C9: 기망형 | D9: 허위 정체성·성과·후기·사연을 사용해 신뢰를 조작하고 정보·자금·행동을 유도 | E9: XR-C-TA0001; XR-C-TA0002; XR-C-TA0004; XR-C-TA0006; XR-C-TA0007; XR-C-TA0008; XR-C-TA0015 | F9: XR-C-TE0002; XR-C-TE0005; XR-C-TE0006; XR-C-TE0007; XR-C-TE0011; XR-C-TE0018; XR-C-TE0019; XR-C-TE0020; XR-C-TE0021; XR-C-TE0022; XR-C-TE0030; XR-C-TE0036; XR-C-TE0037 | G9: claim_strength, impersonation_role, payment_stage_count, requested_field_types | H9: 사칭·피싱·투자기망 등은 범죄 분야와 변수로 확장
A10: XR-C-BP0006 | B10: PROMOTE | C10: 홍보·유입형 | D10: 범죄 관련 제공물·채널의 노출과 반응을 확대하고 다음 접촉 단계로 유입 | E10: XR-C-TA0001; XR-C-TA0003; XR-C-TA0004; XR-C-TA0013; XR-C-TA0014; XR-C-TA0015 | F10: XR-C-TE0003; XR-C-TE0004; XR-C-TE0008; XR-C-TE0009; XR-C-TE0010; XR-C-TE0011; XR-C-TE0028; XR-C-TE0029; XR-C-TE0030; XR-C-TE0031; XR-C-TE0034; XR-C-TE0037 | G10: marker_set_id, preview_ratio, amplification_weight, signal_threshold | H10: 판매 여부 없이 채널·제공물 노출만 수행할 수 있음
A11: XR-C-BP0007 | B11: PRODUCE | C11: 제작형 | D11: 불법 제작 가능성과 선택 항목을 제시하고 의뢰를 받은 뒤 합성 자리표시자 자산을 구성 | E11: XR-C-TA0003; XR-C-TA0009; XR-C-TA0010; XR-C-TA0015 | F11: XR-C-TE0023; XR-C-TE0024; XR-C-TE0025; XR-C-TE0030; XR-C-TE0031 | G11: capability_level, option_set_id, asset_type, risk_label | H11: 시뮬레이션은 합성 자산 메타데이터만 생성
A12: XR-C-BP0008 | B12: ACQUIRE | C12: 정보·계정 확보형 | D12: 인증·신청·상담 등의 명목으로 가상 개인정보·인증정보 제출을 유도 | E12: XR-C-TA0001; XR-C-TA0002; XR-C-TA0006; XR-C-TA0008; XR-C-TA0015 | F12: XR-C-TE0003; XR-C-TE0018; XR-C-TE0021; XR-C-TE0022; XR-C-TE0030; XR-C-TE0036; XR-C-TE0037 | G12: requested_field_types, verification_type, synthetic_form_id, signal_threshold | H12: 실제 개인정보·자격증명 저장 금지
A13: XR-C-BP0009 | B13: EXPOSE | C13: 피해자 특정·노출형 | D13: 가상 피해자 식별 단서를 합성 콘텐츠와 결합하여 게시·확산 | E13: XR-C-TA0001; XR-C-TA0003; XR-C-TA0011; XR-C-TA0012; XR-C-TA0013; XR-C-TA0015 | F13: XR-C-TE0004; XR-C-TE0026; XR-C-TE0027; XR-C-TE0029; XR-C-TE0030; XR-C-TE0031; XR-C-TE0034 | G13: identifier_types, marker_set_id, account_limit, obfuscation_strength | H13: 실존 인물 식별자는 입력·출력 모두 금지

Sheet 08_코드Enum
A1: 코드 Enum·직렬화 키
A2: 영문 code는 Enum·함수명에 사용하고 XR-* ID는 저장·교환·로그의 불변 식별자로 사용
A4: enum_class | B4: id | C4: code | D4: enum_member | E4: JSON_key | F4: registry_path
A5: CriminalTactic | B5: XR-C-TA0001 | C5: criminal_target_discovery | D5: CRIMINAL_TARGET_DISCOVERY | E5: tactic_ids | F5: CriminalTTPRegistry.tactics
A6: CriminalTactic | B6: XR-C-TA0002 | C6: deceptive_credibility_manipulation | D6: DECEPTIVE_CREDIBILITY_MANIPULATION | E6: tactic_ids | F6: CriminalTTPRegistry.tactics
A7: CriminalTactic | B7: XR-C-TA0003 | C7: illicit_offer_exposure | D7: ILLICIT_OFFER_EXPOSURE | E7: tactic_ids | F7: CriminalTTPRegistry.tactics
A8: CriminalTactic | B8: XR-C-TA0004 | C8: illicit_demand_acquisition | D8: ILLICIT_DEMAND_ACQUISITION | E8: tactic_ids | F8: CriminalTTPRegistry.tactics
A9: CriminalTactic | B9: XR-C-TA0005 | C9: criminal_collaborator_recruitment | D9: CRIMINAL_COLLABORATOR_RECRUITMENT | E9: tactic_ids | F9: CriminalTTPRegistry.tactics
A10: CriminalTactic | B10: XR-C-TA0006 | C10: offplatform_contact_transition | D10: OFFPLATFORM_CONTACT_TRANSITION | E10: tactic_ids | F10: CriminalTTPRegistry.tactics
A11: CriminalTactic | B11: XR-C-TA0007 | C11: illicit_value_acquisition | D11: ILLICIT_VALUE_ACQUISITION | E11: tactic_ids | F11: CriminalTTPRegistry.tactics
A12: CriminalTactic | B12: XR-C-TA0008 | C12: personal_data_credential_acquisition | D12: PERSONAL_DATA_CREDENTIAL_ACQUISITION | E12: tactic_ids | F12: CriminalTTPRegistry.tactics
A13: CriminalTactic | B13: XR-C-TA0009 | C13: illicit_commission_acquisition | D13: ILLICIT_COMMISSION_ACQUISITION | E13: tactic_ids | F13: CriminalTTPRegistry.tactics
A14: CriminalTactic | B14: XR-C-TA0010 | C14: illicit_content_production | D14: ILLICIT_CONTENT_PRODUCTION | E14: tactic_ids | F14: CriminalTTPRegistry.tactics
A15: CriminalTactic | B15: XR-C-TA0011 | C15: victim_identification | D15: VICTIM_IDENTIFICATION | E15: tactic_ids | F15: CriminalTTPRegistry.tactics
... A107: CriminalBehaviorPattern | B107: XR-C-BP0009 | C107: EXPOSE | D107: EXPOSE | E107: primary_behavior_pattern_id | F107: CriminalProfile.behavior_patterns

Sheet 09_구현스키마
A1: 에이전트 환경설정·이산사건 구현 스키마
A2: 하나의 UserAgent 클래스에 프로필 환경설정을 주입하고 TTPComposer가 XR-C 의미 실행과 XR-P 게시 실행을 결합함
A4: object | B4: field | C4: type | D4: constraint/example | E4: required | F4: description
A5: CriminalProfile | B5: criminal_type_id | C5: string | D5: XR-C-UT#### | E5: 필수 | F5: 범죄자 유형 불변 ID
A6: CriminalProfile | B6: primary_behavior_pattern_id | C6: string | D6: XR-C-BP#### | E6: 필수 | F6: 주 행위형
A7: CriminalProfile | B7: secondary_behavior_pattern_ids | C7: array<string> | D7: XR-C-BP####[] | E7: 선택 | F7: 보조 행위형 0개 이상
A8: CriminalProfile | B8: crime_domain_id | C8: string | D8: XR-C-CD#### | E8: 필수 | F8: 범죄 분야
A9: CriminalProfile | B9: domain_variables | C9: object | D9: 도메인 스키마 | E9: 필수 | F9: 분야 특화 변수
A10: CriminalProfile | B10: quantitative_behavior | C10: object | D10: 15개 7일 정량속성 | E10: 필수 | F10: L0~L5 범위에서 샘플링
A11: CriminalProfile | B11: criminal_technique_weights | C11: map<string,number> | D11: 0.0~1.0 | E11: 필수 | F11: Technique 선택 확률 가중치
A12: CriminalProfile | B12: platform_technique_weights | C12: map<string,number> | D12: 0.0~1.0 | E12: 필수 | F12: 상속 플랫폼 Technique 가중치
A13: TTPPlan | B13: tactic_ids | C13: array<string> | D13: XR-C-TA####[] | E13: 필수 | F13: 현재 사건이 달성하려는 원자 목적 집합
A14: TTPPlan | B14: criminal_technique_ids | C14: array<string> | D14: XR-C-TE####[] | E14: 필수 | F14: 범죄자 확장 방법 집합
A15: TTPPlan | B15: platform_dependency_ids | C15: array<string> | D15: XR-P-* / XR-U-* | E15: 필수 | F15: 상속 플랫폼 실행 요소
... A24: JSON예시 | B24: serialized_event | C24: json | D24: {"event_id":"EVT-000042","round_id":"ROUND-0002","event_time":"2026-01-08T10:20:00+09:00","agent_id":"AGENT-C-0010","criminal_type_id":"XR-C-UT0010","primary_behavior_pattern_id":"XR-C-BP0001","secondary_behavior_pattern_ids":["XR-C-BP0006","XR-C-BP0009"],"tactic_ids":["XR-C-TA0003","XR-C-TA0004","XR-C-TA0012","XR-C-TA0015"],"criminal_technique_ids":["XR-C-TE0004","XR-C-TE0026","XR-C-TE0030","XR-C-TE0031"],"criminal_procedure_sequence":["XR-C-PR0006","XR-C-PR0030","XR-C-PR0032","XR-C-PR0033"],"platform_procedure_sequence":["XR-P-PR0001","XR-P-PR0006","XR-P-PR0007","XR-P-PR0010","XR-P-PR0014"],"content_ref":"SYN-CONTENT-0042","safety":{"synthetic_only":true,"external_network":false,"real_payment":false},"config_version":"criminal-agent-1.1.0"} | E24: 예시 | F24: 복수 XR-C/XR-P Procedure 조합
